<?xml version="1.0"?>
<robot xmlns:xacro="http://www.ros.org/wiki/xacro" name="omni_robot">

  <!-- Define the properties for easier reuse -->
  <xacro:property name="wheel_radius" value="0.05"/>
  <xacro:property name="wheel_width" value="0.02"/>
  <xacro:property name="base_radius" value="0.2"/>

  <!-- Base Link -->
  <link name="base_link">
    <visual>
      <geometry>
        <cylinder radius="${base_radius}" length="0.02"/>
      </geometry>
      <material name="blue">
        <color rgba="0 0 1 1"/>
      </material>
    </visual>
    <collision>
      <geometry>
        <cylinder radius="${base_radius}" length="0.02"/>
      </geometry>
    </collision>
    <inertial>
      <mass value="5.0"/>
      <origin xyz="0 0 0" rpy="0 0 0"/>
      <inertia ixx="0.1" ixy="0.0" ixz="0.0" iyy="0.1" iyz="0.0" izz="0.1"/>
    </inertial>
  </link>

  <!-- Omni Wheels -->
  <xacro:macro name="omni_wheel" params="wheel_name joint_name x y z roll pitch yaw">
    <link name="${wheel_name}">
      <visual>
        <geometry>
          <cylinder radius="${wheel_radius}" length="${wheel_width}"/>
        </geometry>
        <material name="black">
          <color rgba="0 0 0 1"/>
        </material>
      </visual>
      <collision>
        <geometry>
          <cylinder radius="${wheel_radius}" length="${wheel_width}"/>
        </geometry>
      </collision>
      <inertial>
        <mass value="0.1"/>
        <origin xyz="0 0 0" rpy="0 0 0"/>
        <inertia ixx="0.001" ixy="0.0" ixz="0.0" iyy="0.001" iyz="0.0" izz="0.001"/>
      </inertial>
    </link>

    <joint name="${joint_name}" type="continuous">
      <parent link="base_link"/>
      <child link="${wheel_name}"/>
      <origin xyz="${x} ${y} ${z}" rpy="${roll} ${pitch} ${yaw}"/>
      <axis xyz="0 1 0"/>
    </joint>
  </xacro:macro>

  <!-- Wheel 1 -->
  <xacro:omni_wheel wheel_name="wheel_1" joint_name="joint_1" x="${base_radius}" y="0" z="0" roll="0" pitch="1.5708" yaw="0"/>

  <!-- Wheel 2 -->
  <xacro:omni_wheel wheel_name="wheel_2" joint_name="joint_2" x="-0.5*${base_radius}" y="0.5*sqrt(3)*${base_radius}" z="0" roll="0" pitch="1.5708" yaw="2.0944"/>

  <!-- Wheel 3 -->
  <xacro:omni_wheel wheel_name="wheel_3" joint_name="joint_3" x="-0.5*${base_radius}" y="-0.5*sqrt(3)*${base_radius}" z="0" roll="0" pitch="1.5708" yaw="-2.0944"/>

  <!-- Add the caster wheel -->
  <link name="caster_wheel">
    <visual>
      <geometry>
        <sphere radius="0.05"/>
      </geometry>
      <material name="gray">
        <color rgba="0.5 0.5 0.5 1"/>
      </material>
    </visual>
    <collision>
      <geometry>
        <sphere radius="0.05"/>
      </geometry>
    </collision>
    <inertial>
      <mass value="0.1"/>
      <origin xyz="0 0 0" rpy="0 0 0"/>
      <inertia ixx="0.001" ixy="0.0" ixz="0.0" iyy="0.001" iyz="0.0" izz="0.001"/>
    </inertial>
  </link>
  
  <joint name="caster_joint" type="fixed">
    <parent link="base_link"/>
    <child link="caster_wheel"/>
    <origin xyz="0 0 -0.1" rpy="0 0 0"/>
  </joint>

  <!-- Gazebo Plugins -->
  <gazebo>
    <plugin name="gazebo_ros_control" filename="libgazebo_ros_control.so"/>
  </gazebo>
  
  <gazebo>
    <plugin name="diff_drive_controller" filename="libgazebo_ros_diff_drive.so">
      <ros>
        <namespace>/omni_robot</namespace>
        <remapping>cmd_vel:=cmd_vel</remapping>
        <remapping>odom:=odom</remapping>
      </ros>
      <legacyMode>false</legacyMode>
      <alwaysOn>true</alwaysOn>
      <updateRate>100.0</updateRate>
      <leftJoint>joint_1</leftJoint>
      <rightJoint>joint_2</rightJoint>
      <wheelSeparation>${base_radius}</wheelSeparation>
      <wheelDiameter>${wheel_radius}*2</wheelDiameter>
      <robotBaseFrame>base_link</robotBaseFrame>
      <odometryFrame>odom</odometryFrame>
      <odometryTopic>odom</odometryTopic>
      <cmdVelTopic>cmd_vel</cmdVelTopic>
    </plugin>
  </gazebo>

</robot>